Traceback (most recent call last):
  File "c:\users\linigodelacruz\appdata\local\continuum\anaconda3\envs\wintest\lib\site-packages\nbclient\client.py", line 567, in _async_poll_for_reply
    msg = await ensure_async(self.kc.shell_channel.get_msg(timeout=timeout))
  File "c:\users\linigodelacruz\appdata\local\continuum\anaconda3\envs\wintest\lib\site-packages\nbclient\util.py", line 83, in ensure_async
    result = await obj
  File "c:\users\linigodelacruz\appdata\local\continuum\anaconda3\envs\wintest\lib\site-packages\jupyter_client\asynchronous\channels.py", line 48, in get_msg
    raise Empty
_queue.Empty

During handling of the above exception, another exception occurred:

Traceback (most recent call last):
  File "c:\users\linigodelacruz\appdata\local\continuum\anaconda3\envs\wintest\lib\site-packages\jupyter_cache\executors\utils.py", line 56, in single_nb_execution
    record_timing=False,
  File "c:\users\linigodelacruz\appdata\local\continuum\anaconda3\envs\wintest\lib\site-packages\nbclient\client.py", line 968, in execute
    return NotebookClient(nb=nb, resources=resources, km=km, **kwargs).execute()
  File "c:\users\linigodelacruz\appdata\local\continuum\anaconda3\envs\wintest\lib\site-packages\nbclient\util.py", line 72, in wrapped
    return just_run(coro(*args, **kwargs))
  File "c:\users\linigodelacruz\appdata\local\continuum\anaconda3\envs\wintest\lib\site-packages\nbclient\util.py", line 51, in just_run
    return loop.run_until_complete(coro)
  File "c:\users\linigodelacruz\appdata\local\continuum\anaconda3\envs\wintest\lib\asyncio\base_events.py", line 587, in run_until_complete
    return future.result()
  File "c:\users\linigodelacruz\appdata\local\continuum\anaconda3\envs\wintest\lib\site-packages\nbclient\client.py", line 509, in async_execute
    cell, index, execution_count=self.code_cells_executed + 1
  File "c:\users\linigodelacruz\appdata\local\continuum\anaconda3\envs\wintest\lib\site-packages\nbclient\client.py", line 734, in async_execute_cell
    parent_msg_id, cell, exec_timeout, task_poll_output_msg
  File "c:\users\linigodelacruz\appdata\local\continuum\anaconda3\envs\wintest\lib\site-packages\nbclient\client.py", line 587, in _async_poll_for_reply
    await self._async_handle_timeout(timeout, cell)
  File "c:\users\linigodelacruz\appdata\local\continuum\anaconda3\envs\wintest\lib\site-packages\nbclient\client.py", line 617, in _async_handle_timeout
    "Cell execution timed out", timeout, cell
nbclient.exceptions.CellTimeoutError: A cell timed out while it was being executed, after 30 seconds.
The message was: Cell execution timed out.
Here is a preview of the cell contents:
-------------------
data=pd.read_excel(abs_file_path_SL,header=0)

-------------------

